Workbook

Sheet BatComp
A1: Car PHEV(35 miles) | B1: LFP | C1: LMO | D1: NMC111 | E1: NMC532 | F1: NMC622 | G1: NMC811 | H1: NMC955 | I1: NCA
A2: Active Material | B2: 0.254 | C2: 0.2906 | D2: 0.2487 | E2: 0.2353 | F2: 0.2323 | G2: 0.2257 | H2: 0.2143 | I2: 0.2238
A3: Graphite/Carbon | B3: 0.1305 | C3: 0.1147 | D3: 0.14 | E3: 0.1443 | F3: 0.1452 | G3: 0.1574 | H3: 0.1608 | I3: 0.1479
A4: Silicon | B4: 0 | C4: 0 | D4: 0 | E4: 0 | F4: 0 | G4: 0 | H4: 0 | I4: 0
A5: Binder | B5: 0.0078 | C5: 0.0083 | D5: 0.0079 | E5: 0.0077 | F5: 0.0077 | G5: 0.0078 | H5: 0.0077 | I5: 0.0076
A6: Copper | B6: 0.0872 | C6: 0.08 | D6: 0.077 | E6: 0.0789 | F6: 0.0797 | G6: 0.0855 | H6: 0.0871 | I6: 0.0818
A7: Aluminum Sheet (Automotive) | B7: 0.1211 | C7: 0.1166 | D7: 0.117 | E7: 0.1186 | F7: 0.1191 | G7: 0.1265 | H7: 0.128 | I7: 0.1201
A8: Cast Aluminum | B8: 0 | C8: 0 | D8: 0 | E8: 0 | F8: 0 | G8: 0 | H8: 0 | I8: 0
A9: Electrolyte: LiPF6 | B9: 0.0107 | C9: 0.0098 | D9: 0.0093 | E9: 0.0093 | F9: 0.0093 | G9: 0.0097 | H9: 0.0096 | I9: 0.0092
A10: Electrolyte: Ethylene Carbonate | B10: 0.0298 | C10: 0.0274 | D10: 0.026 | E10: 0.0259 | F10: 0.026 | G10: 0.027 | H10: 0.0268 | I10: 0.0257
A11: Electrolyte: Dimethyl Carbonate | B11: 0.0298 | C11: 0.0274 | D11: 0.026 | E11: 0.0259 | F11: 0.026 | G11: 0.027 | H11: 0.0268 | I11: 0.0257
A12: Plastic: Polypropylene | B12: 0.0163 | C12: 0.0157 | D12: 0.015 | E12: 0.0152 | F12: 0.0153 | G12: 0.0163 | H12: 0.0165 | I12: 0.0155
A13: Plastic: Polyethylene | B13: 0 | C13: 0 | D13: 0 | E13: 0 | F13: 0 | G13: 0 | H13: 0 | I13: 0
... A22: Energy Density(Wh/kg) | B22: 131.48 | C22: 135.63 | D22: 156.99 | E22: 161.81 | F22: 163.05 | G22: 177.59 | H22: 182.59 | I22: 165.9
A26: Car PHEV(50 miles) | B26: LFP | C26: LMO | D26: NMC111 | E26: NMC532 | F26: NMC622 | G26: NMC811 | H26: NMC955 | I26: NCA
A27: Active Material | B27: 0.2734 | C27: 0.3112 | D27: 0.2715 | E27: 0.2591 | F27: 0.256 | G27: 0.2407 | H27: 0.2301 | I27: 0.2501
A28: Graphite/Carbon | B28: 0.1403 | C28: 0.1226 | D28: 0.1525 | E28: 0.1586 | F28: 0.1598 | G28: 0.1676 | H28: 0.1724 | I28: 0.165
A29: Silicon | B29: 0 | C29: 0 | D29: 0 | E29: 0 | F29: 0 | G29: 0 | H29: 0 | I29: 0
A30: Binder | B30: 0.0084 | C30: 0.0089 | D30: 0.0087 | E30: 0.0085 | F30: 0.0085 | G30: 0.0083 | H30: 0.0082 | I30: 0.0085
A31: Copper | B31: 0.0838 | C31: 0.0795 | D31: 0.0703 | E31: 0.0694 | F31: 0.0692 | G31: 0.0679 | H31: 0.0671 | I31: 0.0679
A32: Aluminum Sheet (Automotive) | B32: 0.1204 | C32: 0.1155 | D32: 0.1151 | E32: 0.1158 | F32: 0.1159 | G32: 0.1168 | H32: 0.1173 | I32: 0.1157
A33: Cast Aluminum | B33: 0 | C33: 0 | D33: 0 | E33: 0 | F33: 0 | G33: 0 | H33: 0 | I33: 0
A34: Electrolyte: LiPF6 | B34: 0.0115 | C34: 0.0105 | D34: 0.0101 | E34: 0.01 | F34: 0.01 | G34: 0.0099 | H34: 0.0099 | I34: 0.0099
A35: Electrolyte: Ethylene Carbonate | B35: 0.0321 | C35: 0.0293 | D35: 0.0281 | E35: 0.0279 | F35: 0.0279 | G35: 0.0277 | H35: 0.0275 | I35: 0.0276
A36: Electrolyte: Dimethyl Carbonate | B36: 0.0321 | C36: 0.0293 | D36: 0.0281 | E36: 0.0279 | F36: 0.0279 | G36: 0.0277 | H36: 0.0275 | I36: 0.0276
A37: Plastic: Polypropylene | B37: 0.0172 | C37: 0.0164 | D37: 0.0153 | E37: 0.0151 | F37: 0.0151 | G37: 0.0149 | H37: 0.0148 | I37: 0.0149
A38: Plastic: Polyethylene | B38: 0 | C38: 0 | D38: 0 | E38: 0 | F38: 0 | G38: 0 | H38: 0 | I38: 0
... A47: Energy Density(Wh/kg) | B47: 141.49 | C47: 145.23 | D47: 171.26 | E47: 177.92 | F47: 179.36 | G47: 188.86 | H47: 195.41 | I47: 184.95
A51: Car EV(150 miles) | B51: LFP | C51: LMO | D51: NMC111 | E51: NMC532 | F51: NMC622 | G51: NMC811 | H51: NMC955 | I51: NCA
A52: Active Material | B52: 0.2461 | C52: 0.2803 | D52: 0.2413 | E52: 0.2302 | F52: 0.227 | G52: 0.2133 | H52: 0.2029 | I52: 0.2212
A53: Graphite/Carbon | B53: 0.1276 | C53: 0.1117 | D53: 0.1373 | E53: 0.1427 | F53: 0.1435 | G53: 0.1505 | H53: 0.154 | I53: 0.1478
A54: Silicon | B54: 0 | C54: 0 | D54: 0 | E54: 0 | F54: 0 | G54: 0 | H54: 0 | I54: 0
A55: Binder | B55: 0.0076 | C55: 0.008 | D55: 0.0077 | E55: 0.0076 | F55: 0.0076 | G55: 0.0074 | H55: 0.0073 | I55: 0.0075
A56: Copper | B56: 0.0921 | C56: 0.089 | D56: 0.0815 | E56: 0.0809 | F56: 0.0808 | G56: 0.0802 | H56: 0.08 | I56: 0.08
A57: Aluminum Sheet (Automotive) | B57: 0.1317 | C57: 0.1278 | D57: 0.1281 | E57: 0.129 | F57: 0.1293 | G57: 0.1302 | H57: 0.1312 | I57: 0.1293
A58: Cast Aluminum | B58: 0 | C58: 0 | D58: 0 | E58: 0 | F58: 0 | G58: 0 | H58: 0 | I58: 0
A59: Electrolyte: LiPF6 | B59: 0.0105 | C59: 0.0096 | D59: 0.009 | E59: 0.009 | F59: 0.0089 | G59: 0.0089 | H59: 0.0088 | I59: 0.0088
A60: Electrolyte: Ethylene Carbonate | B60: 0.0292 | C60: 0.0268 | D60: 0.0252 | E60: 0.025 | F60: 0.0249 | G60: 0.0247 | H60: 0.0244 | I60: 0.0246
A61: Electrolyte: Dimethyl Carbonate | B61: 0.0292 | C61: 0.0268 | D61: 0.0252 | E61: 0.025 | F61: 0.0249 | G61: 0.0247 | H61: 0.0244 | I61: 0.0246
A62: Plastic: Polypropylene | B62: 0.0183 | C62: 0.0177 | D62: 0.0162 | E62: 0.0161 | F62: 0.0161 | G62: 0.0159 | H62: 0.0158 | I62: 0.0158
...

Sheet MatComp
B1: Li | C1: Ni | D1: Co | E1: Mn | F1: Fe | G1: Al | H1: Cu | I1: Graphite | J1: Steel | K1: Plastic
A2: LFP | B2: =RMM!B2/RMM!N2 -> 0.043998327 | C2: =RMM!C2/RMM!N2 -> 0 | D2: =RMM!D2/RMM!N2 -> 0 | E2: =RMM!E2/RMM!N2 -> 0 | F2: =RMM!L2/RMM!N2 -> 0.35399604 | G2: =RMM!J2/RMM!N2 -> 0 | H2: 0 | I2: 0 | J2: 0 | K2: 0
A3: LMO | B3: =RMM!B3/RMM!N3 -> 0.038387727 | C3: =RMM!C3/RMM!N3 -> 0 | D3: =RMM!D3/RMM!N3 -> 0 | E3: =RMM!E3/RMM!N3 -> 0.60767755 | F3: =RMM!L3/RMM!N3 -> 0 | G3: =RMM!J3/RMM!N3 -> 0 | H3: 0 | I3: 0 | J3: 0 | K3: 0
A4: NMC111 | B4: =RMM!B4/RMM!N4 -> 0.071957039 | C4: =RMM!C4/RMM!N4 -> 0.20282258 | D4: =RMM!D4/RMM!N4 -> 0.20365193 | E4: =RMM!E4/RMM!N4 -> 0.1898466 | F4: =RMM!L4/RMM!N4 -> 0 | G4: =RMM!J4/RMM!N4 -> 0 | H4: 0 | I4: 0 | J4: 0 | K4: 0
A5: NMC532 | B5: =RMM!B5/RMM!N5 -> 0.071887606 | C5: =RMM!C5/RMM!N5 -> 0.3039403 | D5: =RMM!D5/RMM!N5 -> 0.12207325 | E5: =RMM!E5/RMM!N5 -> 0.17069707 | F5: =RMM!L5/RMM!N5 -> 0 | G5: =RMM!J5/RMM!N5 -> 0 | H5: 0 | I5: 0 | J5: 0 | K5: 0
A6: NMC622 | B6: =RMM!B6/RMM!N6 -> 0.071609116 | C6: =RMM!C6/RMM!N6 -> 0.36331542 | D6: =RMM!D6/RMM!N6 -> 0.12160035 | E6: =RMM!E6/RMM!N6 -> 0.1133572 | F6: =RMM!L6/RMM!N6 -> 0 | G6: =RMM!J6/RMM!N6 -> 0 | H6: 0 | I6: 0 | J6: 0 | K6: 0
A7: NMC811 | B7: =RMM!B7/RMM!N7 -> 0.071350373 | C7: =RMM!C7/RMM!N7 -> 0.48267022 | D7: =RMM!D7/RMM!N7 -> 0.060580486 | E7: =RMM!E7/RMM!N7 -> 0.056473805 | F7: =RMM!L7/RMM!N7 -> 0 | G7: =RMM!J7/RMM!N7 -> 0 | H7: 0 | I7: 0 | J7: 0 | K7: 0
A8: NMC955 | B8: =RMM!B8/RMM!N8 -> 0.071221702 | C8: =RMM!C8/RMM!N8 -> 0.54202475 | D8: =RMM!D8/RMM!N8 -> 0.030235619 | E8: =RMM!E8/RMM!N8 -> 0.028185981 | F8: =RMM!L8/RMM!N8 -> 0 | G8: =RMM!J8/RMM!N8 -> 0 | H8: 0 | I8: 0 | J8: 0 | K8: 0
A9: NCA | B9: =RMM!B9/RMM!N9 -> 0.07224004 | C9: =RMM!C9/RMM!N9 -> 0.48868862 | D9: =RMM!D9/RMM!N9 -> 0.092003795 | E9: =RMM!E9/RMM!N9 -> 0 | F9: =RMM!L9/RMM!N9 -> 0 | G9: =RMM!J9/RMM!N9 -> 0.014041066 | H9: 0 | I9: 0 | J9: 0 | K9: 0
A10: LTO | B10: =RMM!B12/RMM!$N$12 -> 0.060476555 | C10: =RMM!C12/RMM!$N$12 -> 0 | D10: =RMM!D12/RMM!$N$12 -> 0 | E10: =RMM!E12/RMM!$N$12 -> 0 | F10: =RMM!L12/RMM!$N$12 -> 0 | G10: =RMM!J12/RMM!$N$12 -> 0 | H10: 0 | I10: 0 | J10: 0 | K10: 0
A11: Graphite/Carbon | B11: 0 | C11: 0 | D11: 0 | E11: 0 | F11: 0 | G11: 0 | H11: 0 | I11: 1 | J11: 0 | K11: 0
A12: Silicon | B12: 0 | C12: 0 | D12: 0 | E12: 0 | F12: 0 | G12: 0 | H12: 0 | I12: 0 | J12: 0 | K12: 0
A13: Binder | B13: 0 | C13: 0 | D13: 0 | E13: 0 | F13: 0 | G13: 0 | H13: 0 | I13: 0 | J13: 0 | K13: 0
A14: Copper | B14: 0 | C14: 0 | D14: 0 | E14: 0 | F14: 0 | G14: 0 | H14: 1 | I14: 0 | J14: 0 | K14: 0
A15: Aluminum Sheet (Automotive) | B15: 0 | C15: 0 | D15: 0 | E15: 0 | F15: 0 | G15: 1 | H15: 0 | I15: 0 | J15: 0 | K15: 0
A16: Cast Aluminum | B16: 0 | C16: 0 | D16: 0 | E16: 0 | F16: 0 | G16: 0 | H16: 0 | I16: 0 | J16: 0 | K16: 0
A17: Electrolyte: LiPF6 | B17: 0 | C17: 0 | D17: 0 | E17: 0 | F17: 0 | G17: 0 | H17: 0 | I17: 0 | J17: 0 | K17: 0
A18: Electrolyte: Ethylene Carbonate | B18: 0 | C18: 0 | D18: 0 | E18: 0 | F18: 0 | G18: 0 | H18: 0 | I18: 0 | J18: 0 | K18: 0
A19: Electrolyte: Dimethyl Carbonate | B19: 0 | C19: 0 | D19: 0 | E19: 0 | F19: 0 | G19: 0 | H19: 0 | I19: 0 | J19: 0 | K19: 0
A20: Plastic: Polypropylene | B20: 0 | C20: 0 | D20: 0 | E20: 0 | F20: 0 | G20: 0 | H20: 0 | I20: 0 | J20: 0 | K20: 1
A21: Plastic: Polyethylene | B21: 0 | C21: 0 | D21: 0 | E21: 0 | F21: 0 | G21: 0 | H21: 0 | I21: 0 | J21: 0 | K21: 1
A22: Plastic: Polymer | B22: 0 | C22: 0 | D22: 0 | E22: 0 | F22: 0 | G22: 0 | H22: 0 | I22: 0 | J22: 0 | K22: 1
... A29: Electronic Parts | B29: 0 | C29: 0 | D29: 0 | E29: 0 | F29: 0 | G29: 0 | H29: 0 | I29: 0 | J29: 0 | K29: 0

Sheet RMM
B1: Li | C1: Ni | D1: Co | E1: Mn | F1: H | G1: C | H1: O | I1: F | J1: Al | K1: P | L1: Fe | M1: Ti | N1: Total
A2: LFP | B2: =B$14*B15 -> 6.941 | C2: =C$14*C15 -> 0 | D2: =D$14*D15 -> 0 | E2: =E$14*E15 -> 0 | F2: =F$14*F15 -> 0 | G2: =G$14*G15 -> 0 | H2: =H$14*H15 -> 63.996 | I2: =I$14*I15 -> 0 | ... M2: =M$14*M15 -> 0 | N2: =SUM(B2:L2) -> 157.756 | O2: 1
A3: LMO | B3: =B$14*B16 -> 6.941 | C3: =C$14*C16 -> 0 | D3: =D$14*D16 -> 0 | E3: =E$14*E16 -> 109.876 | F3: =F$14*F16 -> 0 | G3: =G$14*G16 -> 0 | H3: =H$14*H16 -> 63.996 | I3: =I$14*I16 -> 0 | ... M3: =M$14*M16 -> 0 | N3: =SUM(B3:L3) -> 180.813 | O3: 2
A4: NMC111 | B4: =B$14*B17 -> 6.941 | C4: =C$14*C17 -> 19.564333 | D4: =D$14*D17 -> 19.644333 | E4: =E$14*E17 -> 18.312667 | F4: =F$14*F17 -> 0 | G4: =G$14*G17 -> 0 | H4: =H$14*H17 -> 31.998 | I4: =I$14*I17 -> 0 | ... M4: =M$14*M17 -> 0 | N4: =SUM(B4:L4) -> 96.460333 | O4: 3
A5: NMC532 | B5: =B$14*B18 -> 6.941 | C5: =C$14*C18 -> 29.3465 | D5: =D$14*D18 -> 11.7866 | E5: =E$14*E18 -> 16.4814 | F5: =F$14*F18 -> 0 | G5: =G$14*G18 -> 0 | H5: =H$14*H18 -> 31.998 | I5: =I$14*I18 -> 0 | ... M5: =M$14*M18 -> 0 | N5: =SUM(B5:L5) -> 96.5535 | O5: 4
A6: NMC622 | B6: =B$14*B19 -> 6.941 | C6: =C$14*C19 -> 35.2158 | D6: =D$14*D19 -> 11.7866 | E6: =E$14*E19 -> 10.9876 | F6: =F$14*F19 -> 0 | G6: =G$14*G19 -> 0 | H6: =H$14*H19 -> 31.998 | I6: =I$14*I19 -> 0 | ... M6: =M$14*M19 -> 0 | N6: =SUM(B6:L6) -> 96.929 | O6: 5
A7: NMC811 | B7: =B$14*B20 -> 6.941 | C7: =C$14*C20 -> 46.9544 | D7: =D$14*D20 -> 5.8933 | E7: =E$14*E20 -> 5.4938 | F7: =F$14*F20 -> 0 | G7: =G$14*G20 -> 0 | H7: =H$14*H20 -> 31.998 | I7: =I$14*I20 -> 0 | ... M7: =M$14*M20 -> 0 | N7: =SUM(B7:L7) -> 97.2805 | O7: 6
A8: NMC955 | B8: =B$14*B21 -> 6.941 | C8: =C$14*C21 -> 52.8237 | D8: =D$14*D21 -> 2.94665 | E8: =E$14*E21 -> 2.7469 | F8: =F$14*F21 -> 0 | G8: =G$14*G21 -> 0 | H8: =H$14*H21 -> 31.998 | I8: =I$14*I21 -> 0 | ... M8: =M$14*M21 -> 0 | N8: =SUM(B8:L8) -> 97.45625 | O8: 7
A9: NCA | B9: =B$14*B22 -> 6.941 | C9: =C$14*C22 -> 46.9544 | D9: =D$14*D22 -> 8.83995 | E9: =E$14*E22 -> 0 | F9: =F$14*F22 -> 0 | G9: =G$14*G22 -> 0 | H9: =H$14*H22 -> 31.998 | I9: =I$14*I22 -> 0 | ... M9: =M$14*M22 -> 0 | N9: =SUM(B9:L9) -> 96.08245 | O9: 8
A10: LiPF6 | B10: =B$14*B23 -> 6.941 | C10: =C$14*C23 -> 0 | D10: =D$14*D23 -> 0 | E10: =E$14*E23 -> 0 | F10: =F$14*F23 -> 0 | G10: =G$14*G23 -> 0 | H10: =H$14*H23 -> 0 | I10: =I$14*I23 -> 113.988 | ... M10: =M$14*M23 -> 0 | N10: =SUM(B10:L10) -> 151.903 | O10: 9
A11: PVDF | B11: =B$14*B24 -> 0 | C11: =C$14*C24 -> 0 | D11: =D$14*D24 -> 0 | E11: =E$14*E24 -> 0 | F11: =F$14*F24 -> 2.016 | G11: =G$14*G24 -> 24.022 | H11: =H$14*H24 -> 0 | I11: =I$14*I24 -> 37.996 | ... M11: =M$14*M24 -> 0 | N11: =SUM(B11:L11) -> 64.034 | O11: 10
A12: LTO | B12: =B$14*B25 -> 27.764 | C12: =C$14*C25 -> 0 | D12: =D$14*D25 -> 0 | E12: =E$14*E25 -> 0 | F12: =F$14*F25 -> 0 | G12: =G$14*G25 -> 0 | H12: =H$14*H25 -> 191.988 | I12: =I$14*I25 -> 0 | ... M12: =M$14*M25 -> 239.335 | N12: =SUM(B12:M12) -> 459.087 | O12: 11
B13: 1 | C13: 2 | D13: 3 | E13: 4 | F13: 5 | G13: 6 | H13: 7 | I13: 8 | J13: 9 | K13: 10 | L13: 11 | M13: 12
B14: 6.941 | C14: 58.693 | D14: 58.933 | E14: 54.938 | F14: 1.008 | G14: 12.011 | H14: 15.999 | I14: 18.998 | J14: 26.982 | K14: 30.974 | L14: 55.845 | M14: 47.867
B15: 1 | H15: 4 | K15: 1 | L15: 1
B16: 1 | E16: 2 | H16: 4
B17: 1 | C17: 0.33333333 | D17: 0.33333333 | E17: 0.33333333 | H17: 2
B18: 1 | C18: 0.5 | D18: 0.2 | E18: 0.3 | H18: 2
B19: 1 | C19: 0.6 | D19: 0.2 | E19: 0.2 | H19: 2
B20: 1 | C20: 0.8 | D20: 0.1 | E20: 0.1 | H20: 2
B21: 1 | C21: 0.9 | D21: 0.05 | E21: 0.05 | H21: 2
B22: 1 | C22: 0.8 | D22: 0.15 | H22: 2 | J22: 0.05
B23: 1 | I23: 6 | K23: 1
F24: 2 | G24: 2 | I24: 2
B25: 4 | H25: 12 | M25: 5
